<?xml version="1.0"?>
<robot name="abb_irb120"
       xmlns:xi="http://www.w3.org/2001/XInclude"
       xmlns:gazebo="http://playerstage.sourceforge.net/gazebo/xmlschema/#gz"
       xmlns:model="http://playerstage.sourceforge.net/gazebo/xmlschema/#model"
       xmlns:sensor="http://playerstage.sourceforge.net/gazebo/xmlschema/#sensor"
       xmlns:body="http://playerstage.sourceforge.net/gazebo/xmlschema/#body"
       xmlns:geom="http://playerstage.sourceforge.net/gazebo/xmlschema/#geom"
       xmlns:joint="http://playerstage.sourceforge.net/gazebo/xmlschema/#joint"
       xmlns:interface="http://playerstage.sourceforge.net/gazebo/xmlschema/#interface"
       xmlns:rendering="http://playerstage.sourceforge.net/gazebo/xmlschema/#rendering"
       xmlns:renderable="http://playerstage.sourceforge.net/gazebo/xmlschema/#renderable"
       xmlns:controller="http://playerstage.sourceforge.net/gazebo/xmlschema/#controller"
       xmlns:physics="http://playerstage.sourceforge.net/gazebo/xmlschema/#physics">
  <link name="base_link">
    <visual>
      <origin xyz="0 0 0" rpy="0 -0 0"/>
      <geometry>
        <mesh filename="file:///tmp/base_link_mesh.dae" scale="1 1 1" />
      </geometry>
    </visual>
    <collision>
      <origin xyz="0 0 0" rpy="0 -0 0"/>
      <geometry>
        <mesh filename="file:///tmp/base_link_mesh.dae" scale="1 1 1" />
      </geometry>
    </collision>
    <inertial>
      <mass value="6.215" />
      <origin xyz="-0.04204 8.01e-05 0.07964" rpy="0 -0 0"/>
      <inertia ixx="0.0247272" ixy="-8.0784e-05" ixz="0.00130902" iyy="0.0491285" iyz="-8.0419e-06" izz="0.0472376"/>
    </inertial>
  </link>
  <link name="base">
  </link>
  <link name="link_1">
    <visual>
      <origin xyz="0 0 0" rpy="0 -0 0"/>
      <geometry>
        <mesh filename="file:///tmp/link_1_mesh.dae" scale="1 1 1" />
      </geometry>
    </visual>
    <collision>
      <origin xyz="0 0 0" rpy="0 -0 0"/>
      <geometry>
        <mesh filename="file:///tmp/link_1_mesh.dae" scale="1 1 1" />
      </geometry>
    </collision>
    <inertial>
      <mass value="3.067" />
      <origin xyz="9.77e-05 -0.00012 0.23841" rpy="0 -0 0"/>
      <inertia ixx="0.0142175" ixy="-1.28579e-05" ixz="-2.31364e-05" iyy="0.0144041" iyz="1.93404e-05" izz="0.0104533"/>
    </inertial>
  </link>
  <link name="link_2">
    <visual>
      <origin xyz="0 0 0" rpy="0 -0 0"/>
      <geometry>
        <mesh filename="file:///tmp/link_2_mesh.dae" scale="1 1 1" />
      </geometry>
    </visual>
    <collision>
      <origin xyz="0 0 0" rpy="0 -0 0"/>
      <geometry>
        <mesh filename="file:///tmp/link_2_mesh.dae" scale="1 1 1" />
      </geometry>
    </collision>
    <inertial>
      <mass value="3.909" />
      <origin xyz="0.00078 -0.00212 0.10124" rpy="0 -0 0"/>
      <inertia ixx="0.0603111" ixy="9.83431e-06" ixz="5.72407e-05" iyy="0.041569" iyz="-0.00050497" izz="0.0259548"/>
    </inertial>
  </link>
  <link name="link_3">
    <visual>
      <origin xyz="0 0 0" rpy="0 -0 0"/>
      <geometry>
        <mesh filename="file:///tmp/link_3_mesh.dae" scale="1 1 1" />
      </geometry>
    </visual>
    <collision>
      <origin xyz="0 0 0" rpy="0 -0 0"/>
      <geometry>
        <mesh filename="file:///tmp/link_3_mesh.dae" scale="1 1 1" />
      </geometry>
    </collision>
    <inertial>
      <mass value="2.944" />
      <origin xyz="0.02281 0.00106 0.05791" rpy="0 -0 0"/>
      <inertia ixx="0.00835606" ixy="-8.01545e-05" ixz="0.00142884" iyy="0.016713" iyz="-0.000182227" izz="0.0126984"/>
    </inertial>
  </link>
  <link name="link_4">
    <visual>
      <origin xyz="0 0 0" rpy="0 -0 0"/>
      <geometry>
        <mesh filename="file:///tmp/link_4_mesh.dae" scale="1 1 1" />
      </geometry>
    </visual>
    <collision>
      <origin xyz="0 0 0" rpy="0 -0 0"/>
      <geometry>
        <mesh filename="file:///tmp/link_4_mesh.dae" scale="1 1 1" />
      </geometry>
    </collision>
    <inertial>
      <mass value="1.328" />
      <origin xyz="0.2247 0.00015 0.00041" rpy="0 -0 0"/>
      <inertia ixx="0.00284661" ixy="-2.12765e-05" ixz="-1.6435e-05" iyy="0.00401346" iyz="1.31336e-05" izz="0.0052535"/>
    </inertial>
  </link>
  <link name="link_5">
    <visual>
      <origin xyz="0 0 0" rpy="0 -0 0"/>
      <geometry>
        <mesh filename="file:///tmp/link_5_mesh.dae" scale="1 1 1" />
      </geometry>
    </visual>
    <collision>
      <origin xyz="0 0 0" rpy="0 -0 0"/>
      <geometry>
        <mesh filename="file:///tmp/link_5_mesh.dae" scale="1 1 1" />
      </geometry>
    </collision>
    <inertial>
      <mass value="0.546" />
      <origin xyz="-0.00109 3.68e-05 6.22e-05" rpy="0 -0 0"/>
      <inertia ixx="0.000404891" ixy="1.61943e-06" ixz="8.46805e-07" iyy="0.000892825" iyz="-1.51792e-08" izz="0.000815468"/>
    </inertial>
  </link>
  <link name="link_6">
    <visual>
      <origin xyz="0 0 0" rpy="0 -0 0"/>
      <geometry>
        <mesh filename="file:///tmp/link_6_mesh.dae" scale="1 1 1" />
      </geometry>
    </visual>
    <collision>
      <origin xyz="0 0 0" rpy="0 -0 0"/>
      <geometry>
        <mesh filename="file:///tmp/link_6_mesh.dae" scale="1 1 1" />
      </geometry>
    </collision>
    <inertial>
      <mass value="0.137" />
      <origin xyz="-0.00706 -0.00017 -1.32e-06" rpy="0 -0 0"/>
      <inertia ixx="0.001" ixy="0" ixz="0" iyy="0.001" iyz="0" izz="0.001"/>
    </inertial>
  </link>
  <link name="tool0">
  </link>
  <joint name="base_link-base" type="fixed">
    <parent link="base_link"/>
    <child  link="base"/>
    <origin xyz="0 0 0" rpy="0 -0 0 "/>
    <axis   xyz="0 0 0"/>
    <dynamics damping="0.2" friction="0" />
  </joint>
  <joint name="joint_1" type="revolute">
    <parent link="base_link"/>
    <child  link="link_1"/>
    <origin xyz="0 0 0" rpy="0 -0 0 "/>
    <axis   xyz="0 0 1"/>
    <limit lower="-2.87979" upper="2.87979" effort="100" velocity="4.36332" />
    <dynamics damping="0" friction="0" />
  </joint>
  <joint name="joint_2" type="revolute">
    <parent link="link_1"/>
    <child  link="link_2"/>
    <origin xyz="0 0 0.29" rpy="0 -0 0 "/>
    <axis   xyz="0 1 0"/>
    <limit lower="-1.91986" upper="1.91986" effort="100" velocity="4.36332" />
    <dynamics damping="0" friction="0" />
  </joint>
  <joint name="joint_3" type="revolute">
    <parent link="link_2"/>
    <child  link="link_3"/>
    <origin xyz="0 0 0.27" rpy="0 -0 0 "/>
    <axis   xyz="0 1 0"/>
    <limit lower="-1.91986" upper="1.22173" effort="100" velocity="4.36332" />
    <dynamics damping="0" friction="0" />
  </joint>
  <joint name="joint_4" type="revolute">
    <parent link="link_3"/>
    <child  link="link_4"/>
    <origin xyz="0 0 0.07" rpy="0 -0 0 "/>
    <axis   xyz="1 0 0"/>
    <limit lower="-2.79253" upper="2.79253" effort="100" velocity="5.58505" />
    <dynamics damping="0" friction="0" />
  </joint>
  <joint name="joint_5" type="revolute">
    <parent link="link_4"/>
    <child  link="link_5"/>
    <origin xyz="0.302 0 0" rpy="0 -0 0 "/>
    <axis   xyz="0 1 0"/>
    <limit lower="-2.0944" upper="2.0944" effort="100" velocity="5.58505" />
    <dynamics damping="0" friction="0" />
  </joint>
  <joint name="joint_6" type="revolute">
    <parent link="link_5"/>
    <child  link="link_6"/>
    <origin xyz="0.072 0 0" rpy="0 -0 0 "/>
    <axis   xyz="1 0 0"/>
    <limit lower="-6.98132" upper="6.98132" effort="100" velocity="7.33038" />
    <dynamics damping="0" friction="0" />
  </joint>
  <joint name="joint6-tool0" type="fixed">
    <parent link="link_6"/>
    <child  link="tool0"/>
    <origin xyz="0 0 0" rpy="0 -0 0 "/>
    <axis   xyz="0 0 0"/>
    <dynamics damping="0.2" friction="0" />
  </joint>
</robot>
